Function main() throws an exception...
The handler itself throws the same exception...